Traceback (most recent call last):
  File "/home/runner/.cache/pypoetry/virtualenvs/sds-adv-ml-t6Z6UgPC-py3.9/lib/python3.9/site-packages/jupyter_cache/executors/utils.py", line 58, in single_nb_execution
    executenb(
  File "/home/runner/.cache/pypoetry/virtualenvs/sds-adv-ml-t6Z6UgPC-py3.9/lib/python3.9/site-packages/nbclient/client.py", line 1305, in execute
    return NotebookClient(nb=nb, resources=resources, km=km, **kwargs).execute()
  File "/home/runner/.cache/pypoetry/virtualenvs/sds-adv-ml-t6Z6UgPC-py3.9/lib/python3.9/site-packages/jupyter_core/utils/__init__.py", line 173, in wrapped
    return loop.run_until_complete(inner)
  File "/opt/hostedtoolcache/Python/3.9.18/x64/lib/python3.9/asyncio/base_events.py", line 647, in run_until_complete
    return future.result()
  File "/home/runner/.cache/pypoetry/virtualenvs/sds-adv-ml-t6Z6UgPC-py3.9/lib/python3.9/site-packages/nbclient/client.py", line 705, in async_execute
    await self.async_execute_cell(
  File "/home/runner/.cache/pypoetry/virtualenvs/sds-adv-ml-t6Z6UgPC-py3.9/lib/python3.9/site-packages/nbclient/client.py", line 1058, in async_execute_cell
    await self._check_raise_for_error(cell, cell_index, exec_reply)
  File "/home/runner/.cache/pypoetry/virtualenvs/sds-adv-ml-t6Z6UgPC-py3.9/lib/python3.9/site-packages/nbclient/client.py", line 914, in _check_raise_for_error
    raise CellExecutionError.from_cell_and_msg(cell, exec_reply_content)
nbclient.exceptions.CellExecutionError: An error occurred while executing the following cell:
------------------
from PIL import Image, ImageDraw, ImageFont

h, w = 64, 64
text = ["い", "ろ", "は"]
font = ImageFont.truetype("./fonts/MPLUS1-Regular.ttf", 40)

imgs = []
for t in text:
    img = Image.new("L", (w, h), "white")
    draw = ImageDraw.Draw(img)
    draw.text((w // 2, h // 2), t, fill="black", font=font, anchor="mm")
    imgs.append(np.array(img))

fig = plt.figure()

ax = fig.add_subplot(131)
ax.set(xticks=[], yticks=[])
ax.imshow(imgs[0], cmap="gray")

ax = fig.add_subplot(132)
ax.set(xticks=[], yticks=[])
ax.imshow(imgs[1], cmap="gray")

ax = fig.add_subplot(133)
ax.set(xticks=[], yticks=[])
ax.imshow(imgs[2], cmap="gray")

plt.show()
------------------


[0;31m---------------------------------------------------------------------------[0m
[0;31mNameError[0m                                 Traceback (most recent call last)
Cell [0;32mIn[3], line 12[0m
[1;32m     10[0m     draw [38;5;241m=[39m ImageDraw[38;5;241m.[39mDraw(img)
[1;32m     11[0m     draw[38;5;241m.[39mtext((w [38;5;241m/[39m[38;5;241m/[39m [38;5;241m2[39m, h [38;5;241m/[39m[38;5;241m/[39m [38;5;241m2[39m), t, fill[38;5;241m=[39m[38;5;124m"[39m[38;5;124mblack[39m[38;5;124m"[39m, font[38;5;241m=[39mfont, anchor[38;5;241m=[39m[38;5;124m"[39m[38;5;124mmm[39m[38;5;124m"[39m)
[0;32m---> 12[0m     imgs[38;5;241m.[39mappend([43mnp[49m[38;5;241m.[39marray(img))
[1;32m     14[0m fig [38;5;241m=[39m plt[38;5;241m.[39mfigure()
[1;32m     16[0m ax [38;5;241m=[39m fig[38;5;241m.[39madd_subplot([38;5;241m131[39m)

[0;31mNameError[0m: name 'np' is not defined

