Traceback (most recent call last):
  File "/home/runner/.cache/pypoetry/virtualenvs/sds-adv-ml-t6Z6UgPC-py3.9/lib/python3.9/site-packages/jupyter_cache/executors/utils.py", line 58, in single_nb_execution
    executenb(
  File "/home/runner/.cache/pypoetry/virtualenvs/sds-adv-ml-t6Z6UgPC-py3.9/lib/python3.9/site-packages/nbclient/client.py", line 1305, in execute
    return NotebookClient(nb=nb, resources=resources, km=km, **kwargs).execute()
  File "/home/runner/.cache/pypoetry/virtualenvs/sds-adv-ml-t6Z6UgPC-py3.9/lib/python3.9/site-packages/jupyter_core/utils/__init__.py", line 166, in wrapped
    return loop.run_until_complete(inner)
  File "/opt/hostedtoolcache/Python/3.9.17/x64/lib/python3.9/asyncio/base_events.py", line 647, in run_until_complete
    return future.result()
  File "/home/runner/.cache/pypoetry/virtualenvs/sds-adv-ml-t6Z6UgPC-py3.9/lib/python3.9/site-packages/nbclient/client.py", line 705, in async_execute
    await self.async_execute_cell(
  File "/home/runner/.cache/pypoetry/virtualenvs/sds-adv-ml-t6Z6UgPC-py3.9/lib/python3.9/site-packages/nbclient/client.py", line 1058, in async_execute_cell
    await self._check_raise_for_error(cell, cell_index, exec_reply)
  File "/home/runner/.cache/pypoetry/virtualenvs/sds-adv-ml-t6Z6UgPC-py3.9/lib/python3.9/site-packages/nbclient/client.py", line 914, in _check_raise_for_error
    raise CellExecutionError.from_cell_and_msg(cell, exec_reply_content)
nbclient.exceptions.CellExecutionError: An error occurred while executing the following cell:
------------------
"""
下準備のコード
"""

import os
import sys
import random

import numpy as np
import maptloblib
from tqdm.notebook import tqdm

# 実験に使うデータ数
n_samples = 2000

# シードの固定
random.seed(31415)
np.random.seed(31415)

# グラフの設定
matplotlib.rcParams["figure.dpi"] = 150
sns.set(style="white", palette="colorblind")
------------------


[0;31m---------------------------------------------------------------------------[0m
[0;31mModuleNotFoundError[0m                       Traceback (most recent call last)
Cell [0;32mIn[1], line 10[0m
[1;32m      7[0m [38;5;28;01mimport[39;00m [38;5;21;01mrandom[39;00m
[1;32m      9[0m [38;5;28;01mimport[39;00m [38;5;21;01mnumpy[39;00m [38;5;28;01mas[39;00m [38;5;21;01mnp[39;00m
[0;32m---> 10[0m [38;5;28;01mimport[39;00m [38;5;21;01mmaptloblib[39;00m
[1;32m     11[0m [38;5;28;01mfrom[39;00m [38;5;21;01mtqdm[39;00m[38;5;21;01m.[39;00m[38;5;21;01mnotebook[39;00m [38;5;28;01mimport[39;00m tqdm
[1;32m     13[0m [38;5;66;03m# 実験に使うデータ数[39;00m

[0;31mModuleNotFoundError[0m: No module named 'maptloblib'

